<?xml version="1.0"?>
<robot name="automan_cart">

  <!-- Robot Footprint -->
  <link name="base_footprint"/>

  <joint name="base_joint" type="fixed">
    <parent link="base_footprint"/>
    <child link="base_link"/>
    <origin xyz="0.0 0.0 0.15" rpy="0 0 0"/>
  </joint>


  <!-- base link -->
  <link name="base_link">
  	<visual>
      <origin xyz="0 0 0.0" rpy="0 0 0"/>
      <geometry>
		    <box size="1.0 0.5 0.1"/>
      </geometry>
      <material name="blue">
      	<color rgba="0.1 0.1 1.0 0.5" /> 
      </material>
    </visual>
    <collision>
      <origin xyz="0 0 0.0" rpy="0 0 0"/>
      <geometry>
		    <box size="1.0 0.5 0.1"/>
      </geometry>
      <material name="blue">
      	<color rgba="0.1 0.1 1.0 0.5" /> 
      </material>
    </collision>
    <inertial>
      <mass value="10"/>
      <inertia ixx="0.2166" ixy="0" ixz="0" iyy="0.8416" iyz="0" izz="1.0416"/>
    </inertial>
  </link>

  <link name="front_left_wheel_link">
    <visual>
      <origin xyz="0 0 0" rpy="1.57079 0 0"/>
      <geometry>
        <cylinder length="0.08" radius="0.15"/>
      </geometry>
        <material name="black">
          <color rgba="0.0 0.0 0.0 0.5" /> 
        </material>
    </visual>
    <collision>
      <origin xyz="0 0 0" rpy="1.57079 0 0"/>
      <geometry>
        <cylinder length="0.08" radius="0.15"/>
      </geometry>
        <material name="black">
          <color rgba="0.0 0.0 0.0 0.5" /> 
        </material>
    </collision>
    <inertial>
      <mass value="0.5"/>
      <inertia ixx="0.003079" ixy="0" ixz="0" iyy="0.003079" iyz="0" izz="0.005625"/>
    </inertial>
  </link>

  <link name="front_right_wheel_link">
    <visual>
      <origin xyz="0 0 0" rpy="1.57079 0 0"/>
      <geometry>
        <cylinder length="0.08" radius="0.15"/>
      </geometry>
        <material name="black">
          <color rgba="0.0 0.0 0.0 0.5" /> 
        </material>
    </visual>
    <collision>
      <origin xyz="0 0 0" rpy="1.57079 0 0"/>
      <geometry>
        <cylinder length="0.08" radius="0.15"/>
      </geometry>
        <material name="black">
          <color rgba="0.0 0.0 0.0 0.5" /> 
        </material>
    </collision>
    <inertial>
      <mass value="0.5"/>
      <inertia ixx="0.003079" ixy="0" ixz="0" iyy="0.003079" iyz="0" izz="0.005625"/>
    </inertial>
  </link>

  <link name="rear_left_wheel_link">
    <visual>
      <origin xyz="0 0 0" rpy="1.57079 0 0"/>
      <geometry>
        <cylinder length="0.08" radius="0.15"/>
      </geometry>
        <material name="black">
          <color rgba="0.0 0.0 0.0 0.5" /> 
        </material>
    </visual>
    <collision>
      <origin xyz="0 0 0" rpy="1.57079 0 0"/>
      <geometry>
        <cylinder length="0.08" radius="0.15"/>
      </geometry>
        <material name="black">
          <color rgba="0.0 0.0 0.0 0.5" /> 
        </material>
    </collision>
    <inertial>
      <mass value="0.5"/>
      <inertia ixx="0.003079" ixy="0" ixz="0" iyy="0.003079" iyz="0" izz="0.005625"/>
    </inertial>
  </link>

  <link name="rear_right_wheel_link">
    <visual>
      <origin xyz="0 0 0" rpy="1.57079 0 0"/>
      <geometry>
        <cylinder length="0.08" radius="0.15"/>
      </geometry>
        <material name="black">
          <color rgba="0.0 0.0 0.0 0.5" /> 
        </material>
    </visual>
    <collision>
      <origin xyz="0 0 0" rpy="1.57079 0 0"/>
      <geometry>
        <cylinder length="0.08" radius="0.15"/>
      </geometry>
        <material name="black">
          <color rgba="0.0 0.0 0.0 0.5" /> 
        </material>
    </collision>
    <inertial>
      <mass value="0.5"/>
      <inertia ixx="0.003079" ixy="0" ixz="0" iyy="0.003079" iyz="0" izz="0.005625"/>
    </inertial>
  </link>
    
  <joint name="front_left_wheel_joint" type="continuous">
    <parent link="base_link" />
    <child link="front_left_wheel_link" />
    <origin xyz="0.5 0.5 0" />
    <axis xyz="0 1 0" />
  </joint>

  <joint name="front_right_wheel_joint" type="continuous">
    <parent link="base_link" />
    <child link="front_right_wheel_link" />
    <origin xyz="0.5 -0.5 0" />
    <axis xyz="0 1 0" />
  </joint>

  <joint name="rear_left_wheel_joint" type="continuous">
    <parent link="base_link" />
    <child link="rear_left_wheel_link" />
    <origin xyz="-0.5 0.5 0" />
    <axis xyz="0 1 0" />
  </joint>

  <joint name="rear_right_wheel_joint" type="continuous">
    <parent link="base_link" />
    <child link="rear_right_wheel_link" />
    <origin xyz="-0.5 -0.5 0" />
    <axis xyz="0 1 0" />
  </joint>

  <gazebo reference="front_left_wheel_link">
    <mu1 value="0.8"/>
    <mu2 value="0.2"/>
    <kp value="10000000.0"/>
    <kd value="1.0"/>
    <fdir1 value="0 1 0"/>
    <minDepth value="0.001"/>
    <maxContacts value="1"/>

  </gazebo>
  <gazebo reference="front_right_wheel_link">
    <mu1 value="0.8"/>
    <mu2 value="0.2"/>
    <kp value="10000000.0"/>
    <kd value="1.0"/>
    <fdir1 value="0 1 0"/>
    <minDepth value="0.001"/>
    <maxContacts value="1"/>

  </gazebo>
  <gazebo reference="rear_left_wheel_link">
    <mu1 value="0.8"/>
    <mu2 value="0.2"/>
    <kp value="10000000.0"/>
    <kd value="1.0"/>
    <fdir1 value="0 1 0"/>
    <minDepth value="0.001"/>
    <maxContacts value="1"/>

  </gazebo>
  <gazebo reference="rear_right_wheel_link">
    <mu1 value="0.8"/>
    <mu2 value="0.2"/>
    <kp value="10000000.0"/>
    <kd value="1.0"/>
    <fdir1 value="0 1 0"/>
    <minDepth value="0.001"/>
    <maxContacts value="1"/>

  </gazebo>

  <!-- <gazebo>
    <mu1 value="1.0"/>
    <mu2 value="0.9"/>
    <kp value="10000000.0"/>
    <kd value="1.0"/>
    <fdir1 value="1 0 0"/>
    <minDepth value="0.001"/>
    <maxContacts value="64"/>
  </gazebo> -->

  <!-- laser link -->
  <link name="laser_link">
    <visual>
      <origin xyz="0 0 0" rpy="0 0 0"/>
      <geometry>
        <cylinder length="0.02" radius="0.02"/>
      </geometry>
      <material name="black">
        <color rgba="0.0 0.0 0.0 0.5" /> 
      </material>
    </visual>
    <collision>
      <origin xyz="0 0 0" rpy="0 0 0"/>
      <geometry>
        <cylinder length="0.02" radius="0.02"/>
      </geometry>
      <material name="black">
        <color rgba="0.0 0.0 0.0 0.5" /> 
      </material>
    </collision>
    <inertial>
    <mass value="0.1"/>
      <inertia ixx="0.000190416666667" ixy="0" ixz="0" iyy="0.0001904" iyz="0" izz="0.00036"/>
    </inertial>
  </link>
  
  <!-- laser joint -->
  <joint name="laser_joint" type="fixed">
      <parent link="base_link" />
      <child link="laser_link" />
      <origin xyz="0 0 0.2" />
  </joint>
  
  <gazebo reference="laser_link">            <!-- get laser's link name -->
    <sensor type="ray" name="rplidar">
      <pose>0 0 0 0 0 0</pose>
      <visualize>true</visualize>   <!--gazebo's light can be watched-->
      <update_rate>50</update_rate>
      <ray>
        <scan>
          <horizontal>
            <samples>360</samples>
            <resolution>1</resolution>  <!--pressure of computer's working-->
            <min_angle>-3.14</min_angle>
            <max_angle>3.14</max_angle>
          </horizontal>
        </scan>
        <range>
          <min>0.10</min>           <!--distance-->
          <max>100.0</max>
          <resolution>0.01</resolution>     <!--accuracy-->
        </range>
        <noise>
          <type>gaussian</type> <!--add gaussian in simulation-->
          <mean>0.0</mean>
          <stddev>0.01</stddev>
        </noise>
      </ray>
      <plugin name="gazebo_rplidar" filename="libgazebo_ros_laser.so">
        <topicName>/scan</topicName>
        <frameName>laser_link</frameName>
      </plugin>
    </sensor>
  </gazebo>

  <gazebo>
    <plugin name="skid_steer_drive_controller" filename="libgazebo_ros_skid_steer_drive.so">
      <updateRate>50.0</updateRate>
      <robotNamespace>automan_cart</robotNamespace>
      <leftFrontJoint>front_left_wheel_joint</leftFrontJoint>
      <rightFrontJoint>front_right_wheel_joint</rightFrontJoint>
      <leftRearJoint>rear_left_wheel_joint</leftRearJoint>
      <rightRearJoint>rear_right_wheel_joint</rightRearJoint>
      <wheelSeparation>1.0</wheelSeparation>
      <wheelDiameter>0.3</wheelDiameter>
      <robotBaseFrame>base_link</robotBaseFrame>
      <torque>100</torque>
      <commandTopic>cmd_vel</commandTopic>
      <odometryTopic>odom</odometryTopic>
      <odometryFrame>odom</odometryFrame>
      <broadcastTF>1</broadcastTF>
    </plugin>

  </gazebo>

</robot>